Workbook

Sheet Combined_Dataset
A1: document_id | B1: Brand | C1: Code | D1: code_normalized | E1: alt_codes | F1: entry_type | G1: Fault Description | H1: Fault Type | I1: primary_type | J1: Component Category | K1: Difficulty | L1: difficulty_normalized | M1: severity | N1: cost_min | O1: cost_max | P1: cost_flag | Q1: cost_confidence | R1: Cost Basis / Notes | S1: Cost Source | T1: merged_from | U1: review_flag | V1: severity_basis | W1: doc_text | X1: metadata_json
A2: 1 | B2: Voltas | C2: E1 | D2: E1 | F2: error_code | G2: Indoor unit temperature sensor open/short circuit | H2: Sensor | I2: Sensor | J2: Sensor / Electronic | K2: Easy | L2: Easy | M2: High | N2: 400 | O2: 800 | P2: ok | Q2: sourced | R2: Thermistor replacement, part + labor | S2: appliancefaults.in / uniqrepair.com | T2: 138 | V2: Inferred from fault/component type for prototype; not a manufacturer safety classification. | W2: Brand: Voltas. Error code: E1. Fault: Indoor unit temperature sensor open/short circuit. Fault type: Sensor. Severity: High (inferred prototype label). Difficulty: Easy. Fair repair cost: ₹400–₹800. Cost confidence: sourced. Cost notes: Thermistor replacement, part + labor. | X2: {"document_id": 1, "brand": "Voltas", "code": "E1", "code_normalized": "E1", "entry_type": "error_code", "severity": "High", "cost_min": 400, "cost_max": 800, "cost_flag": "ok", "cost_confidence": "sourced", "primary_type": "Sensor"}
A3: 2 | B3: Voltas | C3: E2 | D3: E2 | F3: error_code | G3: Indoor evaporator coil temperature sensor fault | H3: Sensor | I3: Sensor | J3: Sensor / Electronic | K3: Easy | L3: Easy | M3: Medium | N3: 400 | O3: 800 | P3: ok | Q3: sourced | R3: Thermistor replacement, part + labor | S3: appliancefaults.in / uniqrepair.com | V3: Inferred from fault/component type for prototype; not a manufacturer safety classification. | W3: Brand: Voltas. Error code: E2. Fault: Indoor evaporator coil temperature sensor fault. Fault type: Sensor. Severity: Medium (inferred prototype label). Difficulty: Easy. Fair repair cost: ₹400–₹800. Cost confidence: sourced. Cost notes: Thermistor replacement, part + labor. | X3: {"document_id": 2, "brand": "Voltas", "code": "E2", "code_normalized": "E2", "entry_type": "error_code", "severity": "Medium", "cost_min": 400, "cost_max": 800, "cost_flag": "ok", "cost_confidence": "sourced", "primary_type": "Sensor"}
A4: 3 | B4: Voltas | C4: E3 | D4: E3 | F4: error_code | G4: Outdoor unit temperature sensor fault / possible refrigerant leak | H4: Sensor / Refrigerant | I4: Sensor | J4: Sensor-Electronic or Refrigerant | K4: Moderate | L4: Moderate | M4: Medium | N4: 1500 | O4: 3000 | P4: ok | Q4: sourced | R4: If refrigerant leak: leak test + gas refill (R-32/R-410) | S4: appliancefaults.in / solve24.in | T4: 139 | V4: Inferred from fault/component type for prototype; not a manufacturer safety classification. | W4: Brand: Voltas. Error code: E3. Fault: Outdoor unit temperature sensor fault / possible refrigerant leak. Fault type: Sensor. Severity: Medium (inferred prototype label). Difficulty: Moderate. Fair repair cost: ₹1,500–₹3,000. Cost confidence: sourced. Cost notes: If refrigerant leak: leak test + gas refill (R-32/R-410). | X4: {"document_id": 3, "brand": "Voltas", "code": "E3", "code_normalized": "E3", "entry_type": "error_code", "severity": "Medium", "cost_min": 1500, "cost_max": 3000, "cost_flag": "ok", "cost_confidence": "sourced", "primary_type": "Sensor"}
A5: 4 | B5: Voltas | C5: E4 | D5: E4 | F5: error_code | G5: Indoor room temperature sensor erratic reading | H5: Sensor | I5: Sensor | J5: Sensor / Electronic | K5: Easy | L5: Easy | M5: Medium | N5: 400 | O5: 800 | P5: ok | Q5: sourced | R5: Thermistor replacement | S5: appliancefaults.in | T5: 140 | V5: Inferred from fault/component type for prototype; not a manufacturer safety classification. | W5: Brand: Voltas. Error code: E4. Fault: Indoor room temperature sensor erratic reading. Fault type: Sensor. Severity: Medium (inferred prototype label). Difficulty: Easy. Fair repair cost: ₹400–₹800. Cost confidence: sourced. Cost notes: Thermistor replacement. | X5: {"document_id": 4, "brand": "Voltas", "code": "E4", "code_normalized": "E4", "entry_type": "error_code", "severity": "Medium", "cost_min": 400, "cost_max": 800, "cost_flag": "ok", "cost_confidence": "sourced", "primary_type": "Sensor"}
A6: 5 | B6: Voltas | C6: E5 | D6: E5 | F6: error_code | G6: Communication failure between indoor and outdoor unit | H6: Communication | I6: Communication | J6: Wiring / PCB | K6: Moderate | L6: Moderate | M6: High | N6: 1200 | O6: 3500 | P6: ok | Q6: sourced | R6: Cable check first; PCB repair/replace if persistent | S6: appliancefaults.in / uniqrepair.com | T6: 141 | V6: Inferred from fault/component type for prototype; not a manufacturer safety classification. | W6: Brand: Voltas. Error code: E5. Fault: Communication failure between indoor and outdoor unit. Fault type: Communication. Severity: High (inferred prototype label). Difficulty: Moderate. Fair repair cost: ₹1,200–₹3,500. Cost confidence: sourced. Cost notes: Cable check first; PCB repair/replace if persistent. | X6: {"document_id": 5, "brand": "Voltas", "code": "E5", "code_normalized": "E5", "entry_type": "error_code", "severity": "High", "cost_min": 1200, "cost_max": 3500, "cost_flag": "ok", "cost_confidence": "sourced", "primary_type": "Communication"}
A7: 6 | B7: Voltas | C7: E6 | D7: E6 | F7: error_code | G7: Communication failure indoor unit to outdoor compressor unit | H7: Communication | I7: Communication | J7: Wiring / PCB | K7: Moderate | L7: Moderate | M7: High | N7: 1200 | O7: 3500 | P7: ok | Q7: sourced | R7: Cable/PCB inspection | S7: appliancefaults.in | T7: 142 | V7: Inferred from fault/component type for prototype; not a manufacturer safety classification. | W7: Brand: Voltas. Error code: E6. Fault: Communication failure indoor unit to outdoor compressor unit. Fault type: Communication. Severity: High (inferred prototype label). Difficulty: Moderate. Fair repair cost: ₹1,200–₹3,500. Cost confidence: sourced. Cost notes: Cable/PCB inspection. | X7: {"document_id": 6, "brand": "Voltas", "code": "E6", "code_normalized": "E6", "entry_type": "error_code", "severity": "High", "cost_min": 1200, "cost_max": 3500, "cost_flag": "ok", "cost_confidence": "sourced", "primary_type": "Communication"}
A8: 7 | B8: Voltas | C8: F1 | D8: F1 | F8: error_code | G8: Indoor unit fan motor fault | H8: Motor | I8: Motor | J8: Fan Motor | K8: Moderate | L8: Moderate | M8: Medium | N8: 800 | O8: 2000 | P8: ok | Q8: sourced | R8: Fan motor replacement + labor | S8: appliancefaults.in / solve24.in | V8: Inferred from fault/component type for prototype; not a manufacturer safety classification. | W8: Brand: Voltas. Error code: F1. Fault: Indoor unit fan motor fault. Fault type: Motor. Severity: Medium (inferred prototype label). Difficulty: Moderate. Fair repair cost: ₹800–₹2,000. Cost confidence: sourced. Cost notes: Fan motor replacement + labor. | X8: {"document_id": 7, "brand": "Voltas", "code": "F1", "code_normalized": "F1", "entry_type": "error_code", "severity": "Medium", "cost_min": 800, "cost_max": 2000, "cost_flag": "ok", "cost_confidence": "sourced", "primary_type": "Motor"}
A9: 8 | B9: Voltas | C9: F2 | D9: F2 | F9: error_code | G9: Outdoor unit fan motor fault | H9: Motor | I9: Motor | J9: Fan Motor | K9: Moderate | L9: Moderate | M9: Medium | N9: 800 | O9: 2000 | P9: ok | Q9: sourced | R9: Outdoor fan motor replacement | S9: appliancefaults.in | V9: Inferred from fault/component type for prototype; not a manufacturer safety classification. | W9: Brand: Voltas. Error code: F2. Fault: Outdoor unit fan motor fault. Fault type: Motor. Severity: Medium (inferred prototype label). Difficulty: Moderate. Fair repair cost: ₹800–₹2,000. Cost confidence: sourced. Cost notes: Outdoor fan motor replacement. | X9: {"document_id": 8, "brand": "Voltas", "code": "F2", "code_normalized": "F2", "entry_type": "error_code", "severity": "Medium", "cost_min": 800, "cost_max": 2000, "cost_flag": "ok", "cost_confidence": "sourced", "primary_type": "Motor"}
A10: 9 | B10: Voltas | C10: F9 | D10: F9 | F10: error_code | G10: Outdoor DC fan motor fault (inverter models) - no speed feedback to PCB | H10: Motor / Electronic | I10: Motor | J10: Fan Motor / PCB | K10: Moderate | L10: Moderate | M10: Medium | N10: 1000 | O10: 2500 | P10: ok | Q10: sourced | R10: Inverter DC fan motor or driver board issue | S10: appliancefaults.in | T10: 145 | V10: Inferred from fault/component type for prototype; not a manufacturer safety classification. | W10: Brand: Voltas. Error code: F9. Fault: Outdoor DC fan motor fault (inverter models) - no speed feedback to PCB. Fault type: Motor. Severity: Medium (inferred prototype label). Difficulty: Moderate. Fair repair cost: ₹1,000–₹2,500. Cost confidence: sourced. Cost notes: Inverter DC fan motor or driver board issue. | X10: {"document_id": 9, "brand": "Voltas", "code": "F9", "code_normalized": "F9", "entry_type": "error_code", "severity": "Medium", "cost_min": 1000, "cost_max": 2500, "cost_flag": "ok", "cost_confidence": "sourced", "primary_type": "Motor"}
A11: 10 | B11: Voltas | C11: P0/P1 | D11: P0 | E11: P1 | F11: error_code | G11: Voltage protection tripped - supply outside 180-250V safe range | H11: Electrical | I11: Electrical | J11: Power Supply | K11: Easy | L11: Easy | M11: High | N11: 0 | O11: 500 | P11: zero_min | Q11: sourced | R11: Usually needs stabilizer, not a repair; electrician visit | S11: appliancefaults.in | T11: 146, 147 | V11: Inferred from fault/component type for prototype; not a manufacturer safety classification. | W11: Brand: Voltas. Error code: P0/P1. Fault: Voltage protection tripped - supply outside 180-250V safe range. Fault type: Electrical. Severity: High (inferred prototype label). Difficulty: Easy. Fair repair cost: ₹0–₹500. Cost confidence: sourced. Cost notes: Usually needs stabilizer, not a repair; electrician visit. | X11: {"document_id": 10, "brand": "Voltas", "code": "P0/P1", "code_normalized": "P0", "entry_type": "error_code", "severity": "High", "cost_min": 0, "cost_max": 500, "cost_flag": "zero_min", "cost_confidence": "sourced", "primary_type": "Electrical"}
A12: 11 | B12: Voltas | C12: H6 | D12: H6 | F12: error_code | G12: Blinking pattern indicating outdoor module/board level fault | H12: PCB | I12: PCB / Inverter | J12: PCB | K12: Hard | L12: Hard | M12: High | N12: 3500 | O12: 8000 | P12: ok | Q12: sourced | R12: Outdoor PCB replacement | S12: homeauthority.in | V12: Inferred from fault/component type for prototype; not a manufacturer safety classification. | W12: Brand: Voltas. Error code: H6. Fault: Blinking pattern indicating outdoor module/board level fault. Fault type: PCB / Inverter. Severity: High (inferred prototype label). Difficulty: Hard. Fair repair cost: ₹3,500–₹8,000. Cost confidence: sourced. Cost notes: Outdoor PCB replacement. | X12: {"document_id": 11, "brand": "Voltas", "code": "H6", "code_normalized": "H6", "entry_type": "error_code", "severity": "High", "cost_min": 3500, "cost_max": 8000, "cost_flag": "ok", "cost_confidence": "sourced", "primary_type": "PCB / Inverter"}
A13: 12 | B13: Voltas | C13: EE | D13: EE | F13: error_code | G13: Indoor unit general fault (EEPROM/board) | H13: PCB | I13: PCB / Inverter | J13: PCB | K13: Hard | L13: Hard | M13: High | N13: 3500 | O13: 8000 | P13: ok | Q13: sourced | R13: Board level repair/replace | S13: homeauthority.in | V13: Inferred from fault/component type for prototype; not a manufacturer safety classification. | W13: Brand: Voltas. Error code: EE. Fault: Indoor unit general fault (EEPROM/board). Fault type: PCB / Inverter. Severity: High (inferred prototype label). Difficulty: Hard. Fair repair cost: ₹3,500–₹8,000. Cost confidence: sourced. Cost notes: Board level repair/replace. | X13: {"document_id": 12, "brand": "Voltas", "code": "EE", "code_normalized": "EE", "entry_type": "error_code", "severity": "High", "cost_min": 3500, "cost_max": 8000, "cost_flag": "ok", "cost_confidence": "sourced", "primary_type": "PCB / Inverter"}
A14: 13 | B14: LG | C14: CH01 / E2 | D14: CH01 | E14: E2 | F14: error_code | G14: Indoor pipe/temperature sensor open or short circuit | H14: Sensor | I14: Sensor | J14: Sensor / Electronic | K14: Easy | L14: Easy | M14: High | N14: 400 | O14: 800 | P14: ok | Q14: sourced | R14: Sensor replacement | S14: lg.com support / removeandreplace.com | V14: Inferred from fault/component type for prototype; not a manufacturer safety classification. | W14: Brand: LG. Error code: CH01 / E2. Fault: Indoor pipe/temperature sensor open or short circuit. Fault type: Sensor. Severity: High (inferred prototype label). Difficulty: Easy. Fair repair cost: ₹400–₹800. Cost confidence: sourced. Cost notes: Sensor replacement. | X14: {"document_id": 13, "brand": "LG", "code": "CH01 / E2", "code_normalized": "CH01", "entry_type": "error_code", "severity": "High", "cost_min": 400, "cost_max": 800, "cost_flag": "ok", "cost_confidence": "sourced", "primary_type": "Sensor"}
A15: 14 | B15: LG | C15: CH02 / E1 | D15: CH02 | F15: error_code | G15: Indoor pipe sensor auto-stop protection fault | H15: Sensor | I15: Sensor | J15: Sensor / Electronic | K15: Easy | L15: Easy | M15: Medium | N15: 400 | O15: 800 | P15: ok | Q15: sourced | R15: Sensor replacement | S15: lg.com support | U15: alt code E1 (older LG series) dropped: LG E1 is also used by S.No 122 for a different fault | V15: Inferred from fault/component type for prototype; not a manufacturer safety classification. | W15: Brand: LG. Error code: CH02 / E1. Fault: Indoor pipe sensor auto-stop protection fault. Fault type: Sensor. Severity: Medium (inferred prototype label). Difficulty: Easy. Fair repair cost: ₹400–₹800. Cost confidence: sourced. Cost notes: Sensor replacement. | X15: {"document_id": 14, "brand": "LG", "code": "CH02 / E1", "code_normalized": "CH02", "entry_type": "error_code", "severity": "Medium", "cost_min": 400, "cost_max": 800, "cost_flag": "ok", "cost_confidence": "sourced", "primary_type": "Sensor"}
A16: 15 | B16: LG | C16: CH03 / E3 | D16: CH03 | E16: E3 | F16: error_code | G16: Unit has detected no/insufficient refrigerant | H16: Refrigerant | I16: Refrigerant | J16: Refrigerant System | K16: Moderate | L16: Moderate | M16: High | N16: 1500 | O16: 3000 | P16: ok | Q16: sourced | R16: Leak detection + gas refill required | S16: lg.com support | V16: Inferred from fault/component type for prototype; not a manufacturer safety classification. | W16: Brand: LG. Error code: CH03 / E3. Fault: Unit has detected no/insufficient refrigerant. Fault type: Refrigerant. Severity: High (inferred prototype label). Difficulty: Moderate. Fair repair cost: ₹1,500–₹3,000. Cost confidence: sourced. Cost notes: Leak detection + gas refill required. | X16: {"document_id": 15, "brand": "LG", "code": "CH03 / E3", "code_normalized": "CH03", "entry_type": "error_code", "severity": "High", "cost_min": 1500, "cost_max": 3000, "cost_flag": "ok", "cost_confidence": "sourced", "primary_type": "Refrigerant"}
A17: 16 | B17: LG | C17: CH05 | D17: CH05 | F17: error_code | G17: Communication error between indoor and outdoor unit | H17: Communication | I17: Communication | J17: Wiring / PCB | K17: Moderate | L17: Moderate | M17: High | N17: 1200 | O17: 3500 | P17: ok | Q17: sourced | R17: Wiring check first, then PCB | S17: removeandreplace.com / heatpumpanswers.com | T17: 120 | V17: Inferred from fault/component type for prototype; not a manufacturer safety classification. | W17: Brand: LG. Error code: CH05. Fault: Communication error between indoor and outdoor unit. Fault type: Communication. Severity: High (inferred prototype label). Difficulty: Moderate. Fair repair cost: ₹1,200–₹3,500. Cost confidence: sourced. Cost notes: Wiring check first, then PCB. | X17: {"document_id": 16, "brand": "LG", "code": "CH05", "code_normalized": "CH05", "entry_type": "error_code", "severity": "High", "cost_min": 1200, "cost_max": 3500, "cost_flag": "ok", "cost_confidence": "sourced", "primary_type": "Communication"}
A18: 18 | B18: LG | C18: CH07 | D18: CH07 | F18: error_code | G18: Compressor discharge temperature abnormal, unit shuts down to protect compressor | H18: Compressor | I18: Compressor | J18: Compressor | K18: Hard | L18: Hard | M18: High | N18: 8000 | O18: 18000 | P18: ok | Q18: sourced | R18: May indicate compressor wear/failure | S18: removeandreplace.com | V18: Inferred from fault/component type for prototype; not a manufacturer safety classification. | W18: Brand: LG. Error code: CH07. Fault: Compressor discharge temperature abnormal, unit shuts down to protect compressor. Fault type: Compressor. Severity: High (inferred prototype label). Difficulty: Hard. Fair repair cost: ₹8,000–₹18,000. Cost confidence: sourced. Cost notes: May indicate compressor wear/failure. | X18: {"document_id": 18, "brand": "LG", "code": "CH07", "code_normalized": "CH07", "entry_type": "error_code", "severity": "High", "cost_min": 8000, "cost_max": 18000, "cost_flag": "ok", "cost_confidence": "sourced", "primary_type": "Compressor"}
A19: 19 | B19: LG | C19: CH09 | D19: CH09 | F19: error_code | G19: Control board (EEPROM) cannot read/store data | H19: PCB | I19: PCB / Inverter | J19: PCB | K19: Hard | L19: Hard | M19: High | N19: 3500 | O19: 8000 | P19: ok | Q19: sourced | R19: Control board replacement | S19: northnjhvac.com | V19: Inferred from fault/component type for prototype; not a manufacturer safety classification. | W19: Brand: LG. Error code: CH09. Fault: Control board (EEPROM) cannot read/store data. Fault type: PCB / Inverter. Severity: High (inferred prototype label). Difficulty: Hard. Fair repair cost: ₹3,500–₹8,000. Cost confidence: sourced. Cost notes: Control board replacement. | X19: {"document_id": 19, "brand": "LG", "code": "CH09", "code_normalized": "CH09", "entry_type": "error_code", "severity": "High", "cost_min": 3500, "cost_max": 8000, "cost_flag": "ok", "cost_confidence": "sourced", "primary_type": "PCB / Inverter"}
A20: 21 | B20: LG | C20: CH30 | D20: CH30 | F20: error_code | G20: Supply voltage too low for safe operation | H20: Electrical | I20: Electrical | J20: Power Supply | K20: Easy | L20: Easy | M20: High | N20: 0 | O20: 500 | P20: zero_min | Q20: sourced | R20: Electrician / stabilizer, not appliance repair | S20: lg.com support | V20: Inferred from fault/component type for prototype; not a manufacturer safety classification. | W20: Brand: LG. Error code: CH30. Fault: Supply voltage too low for safe operation. Fault type: Electrical. Severity: High (inferred prototype label). Difficulty: Easy. Fair repair cost: ₹0–₹500. Cost confidence: sourced. Cost notes: Electrician / stabilizer, not appliance repair. | X20: {"document_id": 21, "brand": "LG", "code": "CH30", "code_normalized": "CH30", "entry_type": "error_code", "severity": "High", "cost_min": 0, "cost_max": 500, "cost_flag": "zero_min", "cost_confidence": "sourced", "primary_type": "Electrical"}
A21: 22 | B21: LG | C21: CH38 | D21: CH38 | F21: error_code | G21: Low refrigerant or power-related fault | H21: Refrigerant | I21: Refrigerant | J21: Refrigerant System | K21: Moderate | L21: Moderate | M21: High | N21: 1500 | O21: 3000 | P21: ok | Q21: sourced | R21: Leak check + refill | S21: heatpumpanswers.com | V21: Inferred from fault/component type for prototype; not a manufacturer safety classification. | W21: Brand: LG. Error code: CH38. Fault: Low refrigerant or power-related fault. Fault type: Refrigerant. Severity: High (inferred prototype label). Difficulty: Moderate. Fair repair cost: ₹1,500–₹3,000. Cost confidence: sourced. Cost notes: Leak check + refill. | X21: {"document_id": 22, "brand": "LG", "code": "CH38", "code_normalized": "CH38", "entry_type": "error_code", "severity": "High", "cost_min": 1500, "cost_max": 3000, "cost_flag": "ok", "cost_confidence": "sourced", "primary_type": "Refrigerant"}
A22: 23 | B22: Daikin | C22: A1 | D22: A1 | F22: error_code | G22: Indoor unit PCB defect | H22: PCB | I22: PCB / Inverter | J22: PCB | K22: Hard | L22: Hard | M22: High | N22: 3500 | O22: 8000 | P22: ok | Q22: sourced | R22: Indoor control board replacement | Component-level PCB repair is cheaper (about 1200-3500) when the board is repairable | S22: removeandreplace.com / fixurge.com | T22: 101 | V22: Inferred from fault/component type for prototype; not a manufacturer safety classification. | W22: Brand: Daikin. Error code: A1. Fault: Indoor unit PCB defect. Fault type: PCB / Inverter. Severity: High (inferred prototype label). Difficulty: Hard. Fair repair cost: ₹3,500–₹8,000. Cost confidence: sourced. Cost notes: Indoor control board replacement | Component-level PCB repair is cheaper (about 1200-3500) when the board is repairable. | X22: {"document_id": 23, "brand": "Daikin", "code": "A1", "code_normalized": "A1", "entry_type": "error_code", "severity": "High", "cost_min": 3500, "cost_max": 8000, "cost_flag": "ok", "cost_confidence": "sourced", "primary_type": "PCB / Inverter"}
A23: 24 | B23: Daikin | C23: A3 | D23: A3 | F23: error_code | G23: Drain system malfunction - water not draining, possible clog | H23: Mechanical | I23: Mechanical | J23: Drain System | K23: Easy | L23: Easy | M23: Low | N23: 500 | O23: 1500 | P23: ok | Q23: sourced | R23: Drain pipe/pump cleaning or pump replacement | S23: removeandreplace.com | T23: 102 | V23: Inferred from fault/component type for prototype; not a manufacturer safety classification. | W23: Brand: Daikin. Error code: A3. Fault: Drain system malfunction - water not draining, possible clog. Fault type: Mechanical. Severity: Low (inferred prototype label). Difficulty: Easy. Fair repair cost: ₹500–₹1,500. Cost confidence: sourced. Cost notes: Drain pipe/pump cleaning or pump replacement. | X23: {"document_id": 24, "brand": "Daikin", "code": "A3", "code_normalized": "A3", "entry_type": "error_code", "severity": "Low", "cost_min": 500, "cost_max": 1500, "cost_flag": "ok", "cost_confidence": "sourced", "primary_type": "Mechanical"}
A24: 25 | B24: Daikin | C24: A5 | D24: A5 | F24: error_code | G24: Freeze-up prevention / indoor coil temperature protection | H24: Sensor / Coil | I24: Sensor | J24: Coil / Sensor | K24: Moderate | L24: Moderate | M24: Medium | N24: 800 | O24: 1500 | P24: ok | Q24: sourced | R24: Often dirty filter/airflow issue; sensor check | May be a protection trip needing no part | S24: fixurge.com | T24: 103 | V24: Inferred from fault/component type for prototype; not a manufacturer safety classification. | W24: Brand: Daikin. Error code: A5. Fault: Freeze-up prevention / indoor coil temperature protection. Fault type: Sensor. Severity: Medium (inferred prototype label). Difficulty: Moderate. Fair repair cost: ₹800–₹1,500. Cost confidence: sourced. Cost notes: Often dirty filter/airflow issue; sensor check | May be a protection trip needing no part. | X24: {"document_id": 25, "brand": "Daikin", "code": "A5", "code_normalized": "A5", "entry_type": "error_code", "severity": "Medium", "cost_min": 800, "cost_max": 1500, "cost_flag": "ok", "cost_confidence": "sourced", "primary_type": "Sensor"}
A25: 26 | B25: Daikin | C25: A6 | D25: A6 | F25: error_code | G25: Indoor fan motor lock or overload | H25: Motor | I25: Motor | J25: Fan Motor | K25: Moderate | L25: Moderate | M25: High | N25: 800 | O25: 2000 | P25: ok | Q25: sourced | R25: Fan motor replacement | S25: removeandreplace.com | T25: 214 | V25: Inferred from fault/component type for prototype; not a manufacturer safety classification. | W25: Brand: Daikin. Error code: A6. Fault: Indoor fan motor lock or overload. Fault type: Motor. Severity: High (inferred prototype label). Difficulty: Moderate. Fair repair cost: ₹800–₹2,000. Cost confidence: sourced. Cost notes: Fan motor replacement. | X25: {"document_id": 26, "brand": "Daikin", "code": "A6", "code_normalized": "A6", "entry_type": "error_code", "severity": "High", "cost_min": 800, "cost_max": 2000, "cost_flag": "ok", "cost_confidence": "sourced", "primary_type": "Motor"}
A26: 27 | B26: Daikin | C26: A7 | D26: A7 | F26: error_code | G26: Malfunction of swing motor / louver flap | H26: Motor | I26: Motor | J26: Louver Motor | K26: Easy | L26: Easy | M26: Medium | N26: 500 | O26: 1200 | P26: ok | Q26: sourced | R26: Swing motor replacement | S26: removeandreplace.com | V26: Inferred from fault/component type for prototype; not a manufacturer safety classification. | W26: Brand: Daikin. Error code: A7. Fault: Malfunction of swing motor / louver flap. Fault type: Motor. Severity: Medium (inferred prototype label). Difficulty: Easy. Fair repair cost: ₹500–₹1,200. Cost confidence: sourced. Cost notes: Swing motor replacement. | X26: {"document_id": 27, "brand": "Daikin", "code": "A7", "code_normalized": "A7", "entry_type": "error_code", "severity": "Medium", "cost_min": 500, "cost_max": 1200, "cost_flag": "ok", "cost_confidence": "sourced", "primary_type": "Motor"}
A27: 28 | B27: Daikin | C27: A9 | D27: A9 | F27: error_code | G27: Electronic expansion valve (EEV) malfunction | H27: Valve | I27: Valve | J27: Expansion Valve | K27: Hard | L27: Hard | M27: Low | N27: 3000 | O27: 6000 | P27: ok | Q27: sourced | R27: EEV replacement, refrigerant handling required | S27: removeandreplace.com / fixurge.com | V27: Inferred from fault/component type for prototype; not a manufacturer safety classification. | W27: Brand: Daikin. Error code: A9. Fault: Electronic expansion valve (EEV) malfunction. Fault type: Valve. Severity: Low (inferred prototype label). Difficulty: Hard. Fair repair cost: ₹3,000–₹6,000. Cost confidence: sourced. Cost notes: EEV replacement, refrigerant handling required. | X27: {"document_id": 28, "brand": "Daikin", "code": "A9", "code_normalized": "A9", "entry_type": "error_code", "severity": "Low", "cost_min": 3000, "cost_max": 6000, "cost_flag": "ok", "cost_confidence": "sourced", "primary_type": "Valve"}
A28: 30 | B28: Daikin | C28: C5 | D28: C5 | F28: error_code | G28: Gas pipe thermistor malfunction | H28: Sensor | I28: Sensor | J28: Sensor / Electronic | K28: Easy | L28: Easy | M28: Medium | N28: 400 | O28: 800 | P28: ok | Q28: sourced | R28: Sensor replacement | S28: removeandreplace.com | V28: Inferred from fault/component type for prototype; not a manufacturer safety classification. | W28: Brand: Daikin. Error code: C5. Fault: Gas pipe thermistor malfunction. Fault type: Sensor. Severity: Medium (inferred prototype label). Difficulty: Easy. Fair repair cost: ₹400–₹800. Cost confidence: sourced. Cost notes: Sensor replacement. | X28: {"document_id": 30, "brand": "Daikin", "code": "C5", "code_normalized": "C5", "entry_type": "error_code", "severity": "Medium", "cost_min": 400, "cost_max": 800, "cost_flag": "ok", "cost_confidence": "sourced", "primary_type": "Sensor"}
A29: 31 | B29: Daikin | C29: C9 | D29: C9 | F29: error_code | G29: Air (room) temperature thermistor malfunction | H29: Sensor | I29: Sensor | J29: Sensor / Electronic | K29: Easy | L29: Easy | M29: Medium | N29: 400 | O29: 800 | P29: ok | Q29: sourced | R29: Sensor replacement | S29: removeandreplace.com | V29: Inferred from fault/component type for prototype; not a manufacturer safety classification. | W29: Brand: Daikin. Error code: C9. Fault: Air (room) temperature thermistor malfunction. Fault type: Sensor. Severity: Medium (inferred prototype label). Difficulty: Easy. Fair repair cost: ₹400–₹800. Cost confidence: sourced. Cost notes: Sensor replacement. | X29: {"document_id": 31, "brand": "Daikin", "code": "C9", "code_normalized": "C9", "entry_type": "error_code", "severity": "Medium", "cost_min": 400, "cost_max": 800, "cost_flag": "ok", "cost_confidence": "sourced", "primary_type": "Sensor"}
A30: 33 | B30: Daikin | C30: E3 | D30: E3 | F30: error_code | G30: Activation of high pressure switch | H30: Refrigerant / Pressure | I30: Refrigerant | J30: Refrigerant System | K30: Moderate | L30: Moderate | M30: High | N30: 1500 | O30: 3500 | P30: ok | Q30: sourced | R30: Check for blockage/overcharge, possible leak repair | S30: removeandreplace.com | T30: 216 | V30: Inferred from fault/component type for prototype; not a manufacturer safety classification. | W30: Brand: Daikin. Error code: E3. Fault: Activation of high pressure switch. Fault type: Refrigerant. Severity: High (inferred prototype label). Difficulty: Moderate. Fair repair cost: ₹1,500–₹3,500. Cost confidence: sourced. Cost notes: Check for blockage/overcharge, possible leak repair. | X30: {"document_id": 33, "brand": "Daikin", "code": "E3", "code_normalized": "E3", "entry_type": "error_code", "severity": "High", "cost_min": 1500, "cost_max": 3500, "cost_flag": "ok", "cost_confidence": "sourced", "primary_type": "Refrigerant"}
A31: 34 | B31: Daikin | C31: E4 | D31: E4 | F31: error_code | G31: Activation of low pressure switch | H31: Refrigerant / Pressure | I31: Refrigerant | J31: Refrigerant System | K31: Moderate | L31: Moderate | M31: High | N31: 1500 | O31: 3500 | P31: ok | Q31: sourced | R31: Refrigerant leak likely, leak test + refill | S31: removeandreplace.com | V31: Inferred from fault/component type for prototype; not a manufacturer safety classification. | W31: Brand: Daikin. Error code: E4. Fault: Activation of low pressure switch. Fault type: Refrigerant. Severity: High (inferred prototype label). Difficulty: Moderate. Fair repair cost: ₹1,500–₹3,500. Cost confidence: sourced. Cost notes: Refrigerant leak likely, leak test + refill. | X31: {"document_id": 34, "brand": "Daikin", "code": "E4", "code_normalized": "E4", "entry_type": "error_code", "severity": "High", "cost_min": 1500, "cost_max": 3500, "cost_flag": "ok", "cost_confidence": "sourced", "primary_type": "Refrigerant"}
A32: 35 | B32: Daikin | C32: E5 | D32: E5 | F32: error_code | G32: Compressor overheat protection activated | H32: Compressor | I32: Compressor | J32: Compressor | K32: Hard | L32: Hard | M32: High | N32: 8000 | O32: 18000 | P32: ok | Q32: sourced | R32: Compressor repair/replacement territory | Check capacitor first; can lower cost if compressor is fine | S32: removeandreplace.com / fixurge.com | T32: 105 | V32: Inferred from fault/component type for prototype; not a manufacturer safety classification. | W32: Brand: Daikin. Error code: E5. Fault: Compressor overheat protection activated. Fault type: Compressor. Severity: High (inferred prototype label). Difficulty: Hard. Fair repair cost: ₹8,000–₹18,000. Cost confidence: sourced. Cost notes: Compressor repair/replacement territory | Check capacitor first; can lower cost if compressor is fine. | X32: {"document_id": 35, "brand": "Daikin", "code": "E5", "code_normalized": "E5", "entry_type": "error_code", "severity": "High", "cost_min": 8000, "cost_max": 18000, "cost_flag": "ok", "cost_confidence": "sourced", "primary_type": "Compressor"}
A33: 36 | B33: Daikin | C33: E6 | D33: E6 | F33: error_code | G33: Compressor lock / not starting | H33: Compressor | I33: Compressor | J33: Compressor | K33: Hard | L33: Hard | M33: High | N33: 8000 | O33: 18000 | P33: ok | Q33: sourced | R33: Compressor replacement likely | S33: fixurge.com | V33: Inferred from fault/component type for prototype; not a manufacturer safety classification. | W33: Brand: Daikin. Error code: E6. Fault: Compressor lock / not starting. Fault type: Compressor. Severity: High (inferred prototype label). Difficulty: Hard. Fair repair cost: ₹8,000–₹18,000. Cost confidence: sourced. Cost notes: Compressor replacement likely. | X33: {"document_id": 36, "brand": "Daikin", "code": "E6", "code_normalized": "E6", "entry_type": "error_code", "severity": "High", "cost_min": 8000, "cost_max": 18000, "cost_flag": "ok", "cost_confidence": "sourced", "primary_type": "Compressor"}
A34: 38 | B34: Daikin | C34: U0 | D34: U0 | F34: error_code | G34: Refrigerant shortage or EEV failure | H34: Refrigerant | I34: Refrigerant | J34: Refrigerant System | K34: Moderate | L34: Moderate | M34: High | N34: 1500 | O34: 3000 | P34: ok | Q34: sourced | R34: Leak detection + refill, or EEV replacement | S34: removeandreplace.com | T34: 109 | V34: Inferred from fault/component type for prototype; not a manufacturer safety classification. | W34: Brand: Daikin. Error code: U0. Fault: Refrigerant shortage or EEV failure. Fault type: Refrigerant. Severity: High (inferred prototype label). Difficulty: Moderate. Fair repair cost: ₹1,500–₹3,000. Cost confidence: sourced. Cost notes: Leak detection + refill, or EEV replacement. | X34: {"document_id": 38, "brand": "Daikin", "code": "U0", "code_normalized": "U0", "entry_type": "error_code", "severity": "High", "cost_min": 1500, "cost_max": 3000, "cost_flag": "ok", "cost_confidence": "sourced", "primary_type": "Refrigerant"}
A35: 39 | B35: Daikin | C35: U2 | D35: U2 | F35: error_code | G35: Power supply insufficient | H35: Electrical | I35: Electrical | J35: Power Supply | K35: Easy | L35: Easy | M35: High | N35: 0 | O35: 500 | P35: zero_min | Q35: sourced | R35: Electrician / stabilizer | S35: removeandreplace.com | V35: Inferred from fault/component type for prototype; not a manufacturer safety classification. | W35: Brand: Daikin. Error code: U2. Fault: Power supply insufficient. Fault type: Electrical. Severity: High (inferred prototype label). Difficulty: Easy. Fair repair cost: ₹0–₹500. Cost confidence: sourced. Cost notes: Electrician / stabilizer. | X35: {"document_id": 39, "brand": "Daikin", "code": "U2", "code_normalized": "U2", "entry_type": "error_code", "severity": "High", "cost_min": 0, "cost_max": 500, "cost_flag": "zero_min", "cost_confidence": "sourced", "primary_type": "Electrical"}
A36: 40 | B36: Daikin | C36: U4 | D36: U4 | F36: error_code | G36: Transmission/communication error between indoor and outdoor units | H36: Communication | I36: Communication | J36: Wiring / PCB | K36: Moderate | L36: Moderate | M36: High | N36: 1200 | O36: 3500 | P36: ok | Q36: sourced | R36: Most common Daikin fault - check wiring/connectors first | S36: acerrorcode.com / minisplitsizer.com | T36: 110 | V36: Inferred from fault/component type for prototype; not a manufacturer safety classification. | W36: Brand: Daikin. Error code: U4. Fault: Transmission/communication error between indoor and outdoor units. Fault type: Communication. Severity: High (inferred prototype label). Difficulty: Moderate. Fair repair cost: ₹1,200–₹3,500. Cost confidence: sourced. Cost notes: Most common Daikin fault - check wiring/connectors first. | X36: {"document_id": 40, "brand": "Daikin", "code": "U4", "code_normalized": "U4", "entry_type": "error_code", "severity": "High", "cost_min": 1200, "cost_max": 3500, "cost_flag": "ok", "cost_confidence": "sourced", "primary_type": "Communication"}
A37: 41 | B37: Daikin | C37: L5 | D37: L5 | F37: error_code | G37: Inverter overload | H37: Compressor / Inverter | I37: Compressor | J37: Inverter | K37: Hard | L37: Hard | M37: High | N37: 5000 | O37: 9000 | P37: ok | Q37: sourced | R37: Inverter board or compressor driver repair | S37: hvacinexpert.com | V37: Inferred from fault/component type for prototype; not a manufacturer safety classification. | W37: Brand: Daikin. Error code: L5. Fault: Inverter overload. Fault type: Compressor. Severity: High (inferred prototype label). Difficulty: Hard. Fair repair cost: ₹5,000–₹9,000. Cost confidence: sourced. Cost notes: Inverter board or compressor driver repair. | X37: {"document_id": 41, "brand": "Daikin", "code": "L5", "code_normalized": "L5", "entry_type": "error_code", "severity": "High", "cost_min": 5000, "cost_max": 9000, "cost_flag": "ok", "cost_confidence": "sourced", "primary_type": "Compressor"}
A38: 42 | B38: Daikin | C38: P4 | D38: P4 | F38: error_code | G38: Inverter temperature error | H38: Inverter | I38: PCB / Inverter | J38: Inverter | K38: Hard | L38: Hard | M38: High | N38: 3500 | O38: 8000 | P38: ok | Q38: sourced | R38: Inverter board cooling/replacement | S38: hvacinexpert.com | V38: Inferred from fault/component type for prototype; not a manufacturer safety classification. | W38: Brand: Daikin. Error code: P4. Fault: Inverter temperature error. Fault type: PCB / Inverter. Severity: High (inferred prototype label). Difficulty: Hard. Fair repair cost: ₹3,500–₹8,000. Cost confidence: sourced. Cost notes: Inverter board cooling/replacement. | X38: {"document_id": 42, "brand": "Daikin", "code": "P4", "code_normalized": "P4", "entry_type": "error_code", "severity": "High", "cost_min": 3500, "cost_max": 8000, "cost_flag": "ok", "cost_confidence": "sourced", "primary_type": "PCB / Inverter"}
A39: 43 | B39: Hitachi | C39: E0 | D39: E0 | F39: error_code | G39: Activation of outdoor unit safety/protection device | H39: Electrical / Safety | I39: Electrical | J39: General Protection | K39: Moderate | L39: Moderate | M39: High | N39: 1200 | O39: 3000 | P39: ok | Q39: sourced | R39: Diagnose underlying cause before reset | S39: blog.usro.net | V39: Inferred from fault/component type for prototype; not a manufacturer safety classification. | W39: Brand: Hitachi. Error code: E0. Fault: Activation of outdoor unit safety/protection device. Fault type: Electrical. Severity: High (inferred prototype label). Difficulty: Moderate. Fair repair cost: ₹1,200–₹3,000. Cost confidence: sourced. Cost notes: Diagnose underlying cause before reset. | X39: {"document_id": 43, "brand": "Hitachi", "code": "E0", "code_normalized": "E0", "entry_type": "error_code", "severity": "High", "cost_min": 1200, "cost_max": 3000, "cost_flag": "ok", "cost_confidence": "sourced", "primary_type": "Electrical"}
A40: 44 | B40: Hitachi | C40: E1 | D40: E1 | F40: error_code | G40: Compressor overload condition | H40: Compressor | I40: Compressor | J40: Compressor | K40: Hard | L40: Hard | M40: High | N40: 8000 | O40: 18000 | P40: ok | Q40: sourced | R40: Compressor inspection/replacement | S40: goservicehome.in | V40: Inferred from fault/component type for prototype; not a manufacturer safety classification. | W40: Brand: Hitachi. Error code: E1. Fault: Compressor overload condition. Fault type: Compressor. Severity: High (inferred prototype label). Difficulty: Hard. Fair repair cost: ₹8,000–₹18,000. Cost confidence: sourced. Cost notes: Compressor inspection/replacement. | X40: {"document_id": 44, "brand": "Hitachi", "code": "E1", "code_normalized": "E1", "entry_type": "error_code", "severity": "High", "cost_min": 8000, "cost_max": 18000, "cost_flag": "ok", "cost_confidence": "sourced", "primary_type": "Compressor"}
...

Sheet Merge_Log
A1: Brand | B1: Code | C1: Class | D1: Kept | E1: Retired | F1: Reason
A2: Blue Star | B2: E6 | C2: Same fault, reworded | D2: 52 | E2: 87 | F2: Identical fault and range; kept earlier row.
A3: Daikin | B3: U4 | C3: Same fault, reworded | D3: 40 | E3: 110 | F3: Identical fault and range; kept earlier row.
A4: Daikin | B4: A6 | C4: Same fault, reworded | D4: 26 | E4: 214 | F4: Identical fault and range; kept earlier row.
A5: LG | B5: CH05 | C5: Same fault, reworded | D5: 16 | E5: 120 | F5: Same fault (indoor/outdoor comms), same range; second row hidden by spacing (CH 05).
A6: Voltas | B6: E5 | C6: Same fault, reworded | D6: 5 | E6: 141 | F6: Same fault and range; kept sourced row (also had inconsistent Difficulty: Moderate vs Hard).
A7: Voltas | B7: E6 | C7: Same fault, reworded | D7: 6 | E7: 142 | F7: Same fault and range; kept sourced row (also had inconsistent Difficulty: Moderate vs Hard).
A8: Voltas | B8: F9 | C8: Same fault, reworded | D8: 9 | E8: 145 | F8: Same fault (outdoor DC fan); kept sourced row 9 (1000-2500) over estimated row 145 (1600-4500).
A9: Panasonic | B9: H14 | C9: Same fault, reworded | D9: 223 | E9: 71 | F9: Row 71 says "air flow sensor"; H14 is generally the indoor intake air temperature sensor, so kept row 223.
A10: Blue Star | B10: E1 | C10: Same fault, different cost | D10: 49 | E10: 89 | F10: Kept sourced range 400-800; row 89 was a proxy estimate (800-2000).
A11: Blue Star | B11: E2 | C11: Same fault, different cost | D11: 50 | E11: 90 | F11: Kept sourced range 400-800; row 90 was a proxy estimate (800-2000).
A12: Blue Star | B12: E3 | C12: Same fault, different cost | D12: 51 | E12: 91 | F12: Kept sourced range 1500-3000; row 91 was a proxy estimate (800-2000).
A13: Voltas | B13: E1 | C13: Same fault, different cost | D13: 1 | E13: 138 | F13: Kept sourced range 400-800; row 138 was a proxy estimate (800-2000).
... A30: LG | B30: CH10 | C30: Same code, different fault | D30: 121 | E30: 20 | F30: CH10 = indoor BLDC fan lock (two secondary sources agree); discharge-thermistor row 20 looks wrong. Verify vs manual.
A31: LG | B31: CH06 | C31: Same code, different fault | E31: 17, 219 | F31: Neither row matches secondary sources (CH06 is usually reported as indoor outlet-pipe sensor). Both removed pending manual check.

Sheet Quarantined_Rows
A1: S.No | B1: Brand | C1: Code | D1: Fault Description | E1: Fault Type | F1: Component Category | G1: Difficulty | H1: Est. Cost Range (INR) | I1: Cost Basis / Notes | J1: Cost Source | K1: Kept S.No | L1: Class | M1: Status | N1: Reason
A2: 17 | B2: LG | C2: CH06 | D2: Excessive DC peak current in inverter power circuit | E2: Compressor / Inverter | F2: Inverter / Compressor | G2: Hard | H2: 5000-9000 | I2: Inverter board or compressor driver issue | J2: removeandreplace.com | L2: Same code, different fault | M2: conflict_needs_manual_verification | N2: Neither row matches secondary sources (CH06 is usually reported as indoor outlet-pipe sensor). Both removed pending manual check.
A3: 20 | B3: LG | C3: CH10 | D3: Discharge temperature over 130C - faulty discharge thermistor | E3: Sensor / Compressor | F3: Sensor / Electronic | G3: Moderate | H3: 1200-3000 | I3: Thermistor replacement, monitor compressor health | J3: removeandreplace.com | K3: 121 | L3: Same code, different fault | M3: conflict_needs_manual_verification | N3: CH10 = indoor BLDC fan lock (two secondary sources agree); discharge-thermistor row 20 looks wrong. Verify vs manual.
A4: 104 | B4: Daikin | C4: E1 | D4: Communication failure on indoor PCB | E4: Communication | F4: Communication / Wiring | G4: Moderate | H4: 1200-3500 | I4: Estimated via PCB/control repair bracket | J4: solve24.in | K4: 32 | L4: Same code, different fault | M4: conflict_needs_manual_verification | N4: E1 = outdoor unit PCB defect; row 104 (indoor comms) belongs to U4/U0 family. Verify vs manual.
A5: 106 | B5: Daikin | C5: E7 | D5: Indoor fan motor stopped/stalled | E5: Motor | F5: Fan Motor | G5: Moderate | H5: 1600-4500 | I5: Labor + motor part | J5: solve24.in | K5: 37 | L5: Same code, different fault | M5: conflict_needs_manual_verification | N5: E7 = outdoor fan motor; indoor fan is A6 (already present). Verify vs manual.
A6: 130 | B6: Panasonic | C6: F91 | D6: Voltage protection circuit activated (unstable/out-of-range mains voltage) | E6: Electrical | F6: Power Supply | G6: Easy | H6: No component cost expected | I6: External supply issue, not an AC fault | J6: Inferred, no direct source | K6: 76 | L6: Same code, different fault | M6: conflict_needs_manual_verification | N6: F91 = refrigeration cycle abnormality (low gas); voltage-protection row looks misassigned. Verify vs manual.
A7: 215 | B7: Daikin | C7: C4 | D7: Outdoor coil temperature sensor abnormality | E7: Sensor | F7: Sensor / Electronic | G7: Easy | H7: 400-800 | I7: Thermistor replacement | J7: Estimated (industry service-call benchmarks) | K7: 29 | L7: Same code, different fault | M7: conflict_needs_manual_verification | N7: C4 = liquid pipe thermistor; outdoor coil sensor row looks misassigned. Verify vs manual.
A8: 218 | B8: Samsung | C8: E162 | D8: Outdoor unit compressor position sensor error | E8: Sensor / Compressor | F8: Sensor / Compressor | G8: Moderate | H8: 1200-8000 | I8: Sensor replacement; compressor check if persists | J8: Estimated (industry service-call benchmarks) | K8: 67 | L8: Same code, different fault | M8: conflict_needs_manual_verification | N8: E162 = EEPROM error; compressor position sensor row looks misassigned. Verify vs manual.
A9: 219 | B9: LG | C9: CH 06 | D9: Indoor EEPROM checksum error | E9: PCB | F9: PCB / Control | G9: Hard | H9: 3500-8000 | I9: PCB replacement/reflash | J9: Estimated (industry service-call benchmarks) | L9: Same code, different fault | M9: conflict_needs_manual_verification | N9: Neither row matches secondary sources (CH06 is usually reported as indoor outlet-pipe sensor). Both removed pending manual check.
A10: 71 | B10: Panasonic | C10: H14 | D10: Air flow sensor faulty | E10: Sensor | F10: Sensor / Electronic | G10: Easy | H10: 400-800 | I10: Sensor replacement | J10: fault-codes.jimdofree.com | K10: 223 | L10: Same fault, reworded | M10: duplicate_merged | N10: Row 71 says "air flow sensor"; H14 is generally the indoor intake air temperature sensor, so kept row 223.
A11: 87 | B11: Blue Star | C11: E6 | D11: Communication failure between indoor and outdoor units | E11: Communication | F11: Communication / Wiring | G11: Moderate | H11: 1200-3500 | I11: Estimated via PCB/control repair bracket; may be wiring-only (lower) or board fault (higher) | J11: solve24.in | K11: 52 | L11: Same fault, reworded | M11: duplicate_merged | N11: Identical fault and range; kept earlier row.
A12: 89 | B12: Blue Star | C12: E1 | D12: Indoor air temperature sensor fault | E12: Sensor | F12: Sensor | G12: Moderate | H12: 800-2000 | I12: Estimated (proxy) | J12: solve24.in (proxy) | K12: 49 | L12: Same fault, different cost | M12: duplicate_merged | N12: Kept sourced range 400-800; row 89 was a proxy estimate (800-2000).
A13: 90 | B13: Blue Star | C13: E2 | D13: Indoor evaporator coil temperature sensor fault | E13: Sensor | F13: Sensor | G13: Moderate | H13: 800-2000 | I13: Estimated (proxy) | J13: solve24.in (proxy) | K13: 50 | L13: Same fault, different cost | M13: duplicate_merged | N13: Kept sourced range 400-800; row 90 was a proxy estimate (800-2000).
A14: 91 | B14: Blue Star | C14: E3 | D14: Outdoor condenser coil temperature sensor fault | E14: Sensor | F14: Sensor | G14: Moderate | H14: 800-2000 | I14: Estimated (proxy) | J14: solve24.in (proxy) | K14: 51 | L14: Same fault, different cost | M14: duplicate_merged | N14: Kept sourced range 1500-3000; row 91 was a proxy estimate (800-2000).
A15: 101 | B15: Daikin | C15: A1 | D15: Internal fault on indoor main PCB | E15: PCB | F15: PCB / Control | G15: Moderate | H15: 1200-3500 | I15: Component-level PCB repair | J15: solve24.in | K15: 23 | L15: Same fault, different cost | M15: duplicate_merged | N15: Kept 3500-8000 (full indoor board replacement). Row 101 (1200-3500) is component-level repair; cheaper option noted in Cost Basis / Notes.
A16: 102 | B16: Daikin | C16: A3 | D16: Condensate drain system failure (pump/blocked pipe/overflow) | E16: Drainage / Coil | F16: Drainage | G16: Easy | H16: 400-1800 | I16: Basic service/cleaning bracket; higher if pump replacement needed | J16: India TV/NewsPoint | K16: 24 | L16: Same fault, different cost | M16: duplicate_merged | N16: Kept 500-1500 from the earlier row; both sourced, ranges overlap heavily.
A17: 103 | B17: Daikin | C17: A5 | D17: Protection trip (not a broken part) | E17: Electrical / Safety | F17: Protection / Diagnostic | G17: Easy | H17: No component cost expected | I17: Reset/diagnostic only; investigate underlying trigger before assuming a fault | J17: Inferred, no direct source | K17: 25 | L17: Same fault, different cost | M17: duplicate_merged | N17: Kept the specific freeze-up/coil-protection row (800-1500); row 103 was a generic "protection trip" restatement with no cost. Its point (may need no part) added to notes.
A18: 105 | B18: Daikin | C18: E5 | D18: Compressor overload protection activated | E18: Compressor / Electrical | F18: Compressor / Capacitor | G18: Moderate | H18: 600-9200 | I18: Check capacitor first before compressor repair | J18: ProNearMe; NoBroker | K18: 35 | L18: Same fault, different cost | M18: duplicate_merged | N18: Kept 8000-18000 (sourced). Row 105 (600-9200, capacitor-first) reuses the same template range as Toshiba F3 / Onida E3; its capacitor-first tip added to notes.
A19: 109 | B19: Daikin | C19: U0 | D19: Refrigerant pressure below safe threshold | E19: Refrigerant | F19: Refrigerant | G19: Easy | H19: 1500-3800 | I19: Gas refill cost varies by refrigerant type (R32/R410A/R22); leak must be found first | J19: India TV; ProNearMe | K19: 38 | L19: Same fault, different cost | M19: duplicate_merged | N19: Kept 1500-3000 from the earlier row; ranges nearly identical.
A20: 110 | B20: Daikin | C20: U4 | D20: Communication failure between indoor and outdoor units | E20: Communication | F20: Communication / Wiring | G20: Moderate | H20: 1200-3500 | I20: Estimated via PCB/control repair bracket | J20: solve24.in | K20: 40 | L20: Same fault, reworded | M20: duplicate_merged | N20: Identical fault and range; kept earlier row.
A21: 120 | B21: LG | C21: CH 05 | D21: Communication breakdown between indoor and outdoor units | E21: Communication | F21: Communication / Wiring | G21: Moderate | H21: 1200-3500 | I21: Estimated via PCB/control repair bracket | J21: solve24.in | K21: 16 | L21: Same fault, reworded | M21: duplicate_merged | N21: Same fault (indoor/outdoor comms), same range; second row hidden by spacing (CH 05).
... A33: 224 | B33: Panasonic | C33: H15 | D33: Compressor temperature sensor fault | E33: Sensor / Compressor | F33: Sensor / Compressor | G33: Moderate | H33: 1200-8000 | I33: Sensor replacement, compressor check if persists | J33: Estimated (industry service-call benchmarks) | K33: 72 | L33: Same fault, different cost | M33: duplicate_merged | N33: Kept 1200-3000; row 224 upper bound 8000 was not supported by a distinct source.

Sheet Methodology
A1: RepairCheck dataset: cleaning notes and methodology
A2: Scope | B2: AC fault codes, symptoms and repair costs for the Indian market. Costs are indicative service ranges in INR (parts + labour), compiled from public web sources, not manufacturer price lists.
A3: Document ID | B3: S.No is the unique document ID. Original S.No values are preserved, so gaps are deliberate (retired rows keep their IDs in Quarantined_Rows).
A4: Deduplication | B4: Rows were grouped by brand + normalized code, including alt_codes. Same-fault duplicates were merged (stronger source wins, else earlier row). Same code with a different fault: one row kept, the other moved to Quarantined_Rows with status conflict_needs_manual_verification. See Merge_Log.
A5: Verification status | B5: Code meanings for the conflict pairs were resolved from prior knowledge plus secondary web sources, NOT checked against manufacturer manuals. Rows with review_flag set should be confirmed before the accuracy test. LG CH06 was removed entirely until verified.
A6: Cost fields | B6: cost_min and cost_max are numeric INR. cost_flag: ok, zero_min (min is 0, skip in ratio checks), no_component_cost (external issue, no min/max), variable_no_min (Daikin UF: only a max is stated), wide_range (max/min >= 10).
A7: Cost confidence | B7: cost_confidence is derived from Cost Source: sourced (named site), proxy (a related repair used as a stand-in), estimated (benchmarks, inferred or aggregate). The LLM should hedge on proxy and estimated rows.
A8: Code lookup | B8: code_normalized is uppercase with no spaces; compound codes go to alt_codes (e.g. LG CH01 / E2, Voltas P0/P1). entry_type is error_code, symptom or general; non-error-code rows have a blank code_normalized so they never match a code query.
A9: Labels | B9: primary_type is the first-listed Fault Type, with Hygiene folded into Maintenance and Efficiency/Airflow into Multi-cause. difficulty_normalized maps Easy-Moderate and Easy-Hard to Moderate (conservative). Original columns are kept alongside.
A10: Not Cooling ranges | B10: Lloyd and Voltas Not Cooling rows (400-18000) span every cause from a filter clean to compressor replacement, and are meant to force disambiguation before quoting. The Cross-Brand row (500-3000) covers only the common causes (service, gas refill).
A11: Limitations | B11: Cost estimates are roughly half non-sourced (see counts below). Coverage is uneven: six brands hold most unique codes, so test queries should be drawn mostly from them. Prices vary by city, brand and part availability.
A13: Cost confidence | B13: Rows | C13: Share
A14: sourced | B14: =COUNTIF(Combined_Dataset!$Q$2:$Q$202,A14) | C14: =B14/COUNTA(Combined_Dataset!$A$2:$A$202)
A15: proxy | B15: =COUNTIF(Combined_Dataset!$Q$2:$Q$202,A15) | C15: =B15/COUNTA(Combined_Dataset!$A$2:$A$202)
A16: estimated | B16: =COUNTIF(Combined_Dataset!$Q$2:$Q$202,A16) | C16: =B16/COUNTA(Combined_Dataset!$A$2:$A$202)
A18: Entry type | B18: Rows
A19: error_code | B19: =COUNTIF(Combined_Dataset!$F$2:$F$202,A19)
A20: symptom | B20: =COUNTIF(Combined_Dataset!$F$2:$F$202,A20)
A21: general | B21: =COUNTIF(Combined_Dataset!$F$2:$F$202,A21)
A23: Brand (error codes only) | B23: Rows
A24: Daikin | B24: =COUNTIFS(Combined_Dataset!$B$2:$B$202,A24,Combined_Dataset!$F$2:$F$202,"error_code")
A25: Samsung | B25: =COUNTIFS(Combined_Dataset!$B$2:$B$202,A25,Combined_Dataset!$F$2:$F$202,"error_code")
A26: Voltas | B26: =COUNTIFS(Combined_Dataset!$B$2:$B$202,A26,Combined_Dataset!$F$2:$F$202,"error_code")
A27: Blue Star | B27: =COUNTIFS(Combined_Dataset!$B$2:$B$202,A27,Combined_Dataset!$F$2:$F$202,"error_code")
A28: LG | B28: =COUNTIFS(Combined_Dataset!$B$2:$B$202,A28,Combined_Dataset!$F$2:$F$202,"error_code")
A29: Panasonic | B29: =COUNTIFS(Combined_Dataset!$B$2:$B$202,A29,Combined_Dataset!$F$2:$F$202,"error_code")
A30: Hitachi | B30: =COUNTIFS(Combined_Dataset!$B$2:$B$202,A30,Combined_Dataset!$F$2:$F$202,"error_code")
A31: Carrier | B31: =COUNTIFS(Combined_Dataset!$B$2:$B$202,A31,Combined_Dataset!$F$2:$F$202,"error_code")
A32: Haier | B32: =COUNTIFS(Combined_Dataset!$B$2:$B$202,A32,Combined_Dataset!$F$2:$F$202,"error_code")
A33: Godrej | B33: =COUNTIFS(Combined_Dataset!$B$2:$B$202,A33,Combined_Dataset!$F$2:$F$202,"error_code")
A34: Lloyd | B34: =COUNTIFS(Combined_Dataset!$B$2:$B$202,A34,Combined_Dataset!$F$2:$F$202,"error_code")
A35: O General | B35: =COUNTIFS(Combined_Dataset!$B$2:$B$202,A35,Combined_Dataset!$F$2:$F$202,"error_code")
... A40: Onida | B40: =COUNTIFS(Combined_Dataset!$B$2:$B$202,A40,Combined_Dataset!$F$2:$F$202,"error_code")
A42: Total rows in Combined_Dataset | B42: =COUNTA(Combined_Dataset!$A$2:$A$202)
A44: Segment 1 handoff fixes | B44: Completed
A45: doc_text | B45: Added to every retrieval-ready row; combines brand, code/entry type, fault, primary type, inferred severity, difficulty and cost information.
A46: metadata_json | B46: Added structured metadata for retrieval: document_id, brand, code, normalized code, entry_type, severity, cost_min/max, cost flags/confidence, primary_type.
A47: severity | B47: Added as an inferred prototype label. It is not a manufacturer safety classification and should be presented as such.
A48: manual verification | B48: Six unresolved code conflicts (Daikin C4/E1/E7, Samsung E162, Panasonic F91, LG CH10) are excluded from retrieval-ready rows pending manufacturer-manual verification. LG CH06 remains quarantined as in the original workbook.
A49: test set | B49: Added 18 gold queries in Test_Queries; each points to a correct document_id.
...

Sheet Dataset_Stats
A1: Metric | B1: Value
A2: Retrieval-ready rows | B2: 195
A3: Rows excluded pending manual code verification | B3: 6
A4: Original cleaned rows | B4: 201
A6: Cost confidence | B6: Rows | C6: Share
A7: sourced | B7: 97 | C7: 0.4974359
A8: proxy | B8: 16 | C8: 0.082051282
A9: estimated | B9: 82 | C9: 0.42051282
A11: Entry type | B11: Rows
A12: error_code | B12: 153
A13: symptom | B13: 39
A14: general | B14: 3
A16: Severity (inferred) | B16: Rows
A17: Low | B17: 23
A18: Medium | B18: 67
A19: High | B19: 105
A21: Brand (error-code rows) | B21: Rows
A22: Daikin | B22: 20
A23: Voltas | B23: 16
A24: Samsung | B24: 16
A25: Blue Star | B25: 15
A26: LG | B26: 13
A27: Panasonic | B27: 9
A28: Hitachi | B28: 8
A29: Carrier | B29: 8
A30: Haier | B30: 8
A31: Godrej | B31: 8
A32: Lloyd | B32: 6
A33: O General | B33: 6
... A38: Onida | B38: 3

Sheet Test_Queries
A1: query_id | B1: query | C1: correct_document_id | D1: brand | E1: correct_code | F1: query_type | G1: gold_fault
A2: 1 | B2: Daikin AC shows error code A1 | C2: 23 | D2: Daikin | E2: A1 | F2: exact_code | G2: Indoor unit PCB defect
A3: 2 | B3: My Daikin AC has a problem with PCB / Inverter and is showing A1 | C3: 23 | D3: Daikin | E3: A1 | F3: code_plus_symptom | G3: Indoor unit PCB defect
A4: 3 | B4: Daikin AC shows error code A3 | C4: 24 | D4: Daikin | E4: A3 | F4: exact_code | G4: Drain system malfunction - water not draining, possible clog
A5: 4 | B5: My Daikin AC has a problem with Mechanical and is showing A3 | C5: 24 | D5: Daikin | E5: A3 | F5: code_plus_symptom | G5: Drain system malfunction - water not draining, possible clog
A6: 5 | B6: Daikin AC shows error code A5 | C6: 25 | D6: Daikin | E6: A5 | F6: exact_code | G6: Freeze-up prevention / indoor coil temperature protection
A7: 6 | B7: My Daikin AC has a problem with Sensor and is showing A5 | C7: 25 | D7: Daikin | E7: A5 | F7: code_plus_symptom | G7: Freeze-up prevention / indoor coil temperature protection
A8: 7 | B8: Voltas AC shows error code E1 | C8: 1 | D8: Voltas | E8: E1 | F8: exact_code | G8: Indoor unit temperature sensor open/short circuit
A9: 8 | B9: My Voltas AC has a problem with Sensor and is showing E1 | C9: 1 | D9: Voltas | E9: E1 | F9: code_plus_symptom | G9: Indoor unit temperature sensor open/short circuit
A10: 9 | B10: Voltas AC shows error code E2 | C10: 2 | D10: Voltas | E10: E2 | F10: exact_code | G10: Indoor evaporator coil temperature sensor fault
A11: 10 | B11: My Voltas AC has a problem with Sensor and is showing E2 | C11: 2 | D11: Voltas | E11: E2 | F11: code_plus_symptom | G11: Indoor evaporator coil temperature sensor fault
A12: 11 | B12: Voltas AC shows error code E3 | C12: 3 | D12: Voltas | E12: E3 | F12: exact_code | G12: Outdoor unit temperature sensor fault / possible refrigerant leak
A13: 12 | B13: My Voltas AC has a problem with Sensor and is showing E3 | C13: 3 | D13: Voltas | E13: E3 | F13: code_plus_symptom | G13: Outdoor unit temperature sensor fault / possible refrigerant leak
... A19: 18 | B19: My Voltas AC is having trouble with sensor; what could be wrong? | C19: 3 | D19: Voltas | E19: E3 | F19: vague_symptom | G19: Outdoor unit temperature sensor fault / possible refrigerant leak
